<?xml version="1.0"?>
<robot xmlns:xacro="http://www.ros.org/wiki/xacro" name="finger">

<!-- GEOMETRY -->
    <xacro:macro name="finger_geometry_1">
        <origin rpy="0 0 0" xyz="0 0 0" />
        <geometry>
            <box size="${finger_length} ${finger_width} ${finger_height}"/>
        </geometry>
    </xacro:macro>

    <xacro:macro name="finger_geometry_2">
        <origin rpy="1.57075 0 0" xyz="${finger_length/2} 0 0" />
        <geometry>
            <cylinder length="${finger_width}" radius="${finger_height/2}"/>
        </geometry>
    </xacro:macro>

    <xacro:macro name="finger_geometry_3" params="r x y z side">
        <origin rpy=".000 .000 .785" xyz="${finger_length/2 + x} ${y*side} ${((finger_width/2) + z/2)}"/>
        <geometry>
            <!--sphere radius="${r}"/-->
            <box size="${r} ${r} ${r/3}"/>
        </geometry>
    </xacro:macro>

    <xacro:macro name="finger_geometry_4" params="r x y z side">
        <origin rpy=".785 .000 .000" xyz="${finger_length/2 + x} ${y*side} ${((finger_width/2) + z/2)}"/>
        <geometry>
            <!--sphere radius="${r}"/-->
            <box size="${r/4} ${r} ${r}"/>
        </geometry>
    </xacro:macro>

<!-- MATERIAL -->
    <xacro:macro name="finger_material">
        <material name="finger_color">
            <color rgba=".4 .4 .8 1"/>
        </material>
    </xacro:macro>

<!-- TOOTH -->
    <xacro:macro name="finger_tooth" params="r x y z side">
        <visual>
            <xacro:finger_geometry_3 r="${r}" x="${x}" y="${y}" z="${z}" side="${side}"/>
            <xacro:finger_material/>
        </visual>
        <collision>
            <xacro:finger_geometry_3 r="${r}" x="${x}" y="${y}" z="${z}" side="${side}"/>
        </collision>
    </xacro:macro>

    <xacro:macro name="finger_tooth_first" params="r x y z side">
        <visual>
            <xacro:finger_geometry_4 r="${r}" x="${x}" y="${y}" z="${z}" side="${side}"/>
            <xacro:finger_material/>
        </visual>
        <collision>
            <xacro:finger_geometry_4 r="${r}" x="${x}" y="${y}" z="${z}" side="${side}"/>
        </collision>
    </xacro:macro>


<!-- LINK -->
    <xacro:macro name="finger" params="name parent x y z side">

        <link name="${name}">
            <visual>
                <xacro:finger_geometry_1/>
                <xacro:finger_material/>
            </visual>
            <visual>
                <xacro:finger_geometry_2/>
                <xacro:finger_material/>
            </visual>

            <collision>
                <xacro:finger_geometry_1/>
            </collision>
            <collision>
                <xacro:finger_geometry_2/>
            </collision>

            <!-- TOOTHS -->
            <xacro:finger_tooth_first r=".02" x=".022"  y=".010" z="${.010*side -.020}" side="${side}"/>

            <xacro:finger_tooth r=".006" x=".010"  y=".010" z=".000" side="${side}"/>
            <xacro:finger_tooth r=".006" x=".000"  y=".010" z="-.020" side="${side}"/>
            <xacro:finger_tooth r=".006" x=".010"  y=".010" z="-.040" side="${side}"/>

            <xacro:finger_tooth r=".006" x="-.010"  y=".010" z=".000" side="${side}"/>
            <xacro:finger_tooth r=".006" x="-.020"  y=".010" z="-.020" side="${side}"/>
            <xacro:finger_tooth r=".006" x="-.010"  y=".010" z="-.040" side="${side}"/>

            <xacro:finger_tooth r=".006" x="-.030"  y=".010" z=".000" side="${side}"/>
            <xacro:finger_tooth r=".006" x="-.040"  y=".010" z="-.020" side="${side}"/>
            <xacro:finger_tooth r=".006" x="-.030"  y=".010" z="-.040" side="${side}"/>

            <xacro:finger_tooth r=".006" x="-.050"  y=".010" z=".000" side="${side}"/>
            <xacro:finger_tooth r=".006" x="-.060"  y=".010" z="-.020" side="${side}"/>
            <xacro:finger_tooth r=".006" x="-.050"  y=".010" z="-.040" side="${side}"/>

            <xacro:finger_tooth r=".006" x="-.070"  y=".010" z=".000" side="${side}"/>
            <xacro:finger_tooth r=".006" x="-.080"  y=".010" z="-.020" side="${side}"/>
            <xacro:finger_tooth r=".006" x="-.070"  y=".010" z="-.040" side="${side}"/>

            <xacro:finger_tooth r=".006" x="-.090"  y=".010" z=".000" side="${side}"/>
            <xacro:finger_tooth r=".006" x="-.100"  y=".010" z="-.020" side="${side}"/>
            <xacro:finger_tooth r=".006" x="-.090"  y=".010" z="-.040" side="${side}"/>

            <xacro:finger_tooth r=".008" x="-.020"  y=".010" z=".025" side="${side}"/>
            <xacro:finger_tooth r=".008" x="-.020"  y=".010" z="-.065" side="${side}"/>

            <xacro:finger_tooth r=".008" x="-.070"  y=".010" z=".025" side="${side}"/>
            <xacro:finger_tooth r=".008" x="-.070"  y=".010" z="-.065" side="${side}"/>

            <xacro:finger_tooth r=".008" x="-.120"  y=".010" z=".025" side="${side}"/>
            <xacro:finger_tooth r=".008" x="-.120"  y=".010" z="-.065" side="${side}"/>

            <xacro:finger_tooth r=".008" x="-.170"  y=".010" z=".025" side="${side}"/>
            <xacro:finger_tooth r=".008" x="-.170"  y=".010" z="-.065" side="${side}"/>

            <inertial>
                <origin rpy="0 0 0" xyz="0 0 0" />
                <mass value=".1"/>
                <inertia ixx=".0003" ixy="0.000" ixz="0.000" iyy=".0003" iyz="0.000" izz=".0003"/>
            </inertial>
        </link>
        <gazebo reference="${name}">
            <mu1> 10 </mu1>
            <mu2> 10 </mu2>
            <material> Gazebo/Grey </material>
            <selfCollide>True</selfCollide>
        </gazebo>

        <joint name="${name}_joint" type="prismatic">
            <parent link="${parent}"/>
            <child link="${name}"/>
            <origin rpy="0 0 0" xyz="${x} ${y} ${z}"/>
            <axis xyz="0 ${side*1} 0"/>
            <limit effort="100" velocity="1" lower="0" upper="${link4_width/2 - finger_width}"/>
            <dynamics damping=".1"/>
        </joint>
        <!--gazebo reference="${name}_joint">
            <stopCfm>0.8</stopCfm>
            <stopErp>0.5</stopErp>
            <provideFeedback>true</provideFeedback>
            <implicitSpringDamper>true</implicitSpringDamper>
            <fudgeFactor>0.0</fudgeFactor>
        </gazebo-->
        <gazebo>
            <plugin name="joint_limiter_${name}" filename="libJointLimiter.so">
                <joint>${name}_joint</joint>
                <topic>/simulation/controller/vel/${name}</topic>
                <lower>0</lower>
                <upper>${link4_width/2 - finger_width}</upper>
            </plugin>
        </gazebo>
        <gazebo>
            <plugin name="joint_controller_${name}" filename="libControllerPID.so">
                <joint>${name}_joint</joint>
                <topic>/simulation/controller/vel/${name}</topic>
                <Kp>10</Kp>
                <Ki>0</Ki>
                <Kd>5</Kd>
            </plugin>
        </gazebo>


        <!--transmission name="${name}_transmission">
            <type>transmission_interface/SimpleTransmission</type>
            <joint name="${name}_joint">
                <hardwareInterface>EffortJointInterface</hardwareInterface>
            </joint>
            <actuator name="${name}_motor">
                <hardwareInterface>EffortJointInterface</hardwareInterface>
                <mechanicalReduction>1</mechanicalReduction>
            </actuator>
        </transmission-->

    </xacro:macro>
</robot>
