<?xml version="1.0" ?>
<!-- =================================================================================== -->
<!-- |    This document was autogenerated by xacro from rover.xacro                    | -->
<!-- |    EDITING THIS FILE BY HAND IS NOT RECOMMENDED                                 | -->
<!-- =================================================================================== -->
<robot name="rover" xmlns:xacro="http://www.ros.org/wiki/xacro">
  <gazebo>
    <plugin filename="libgazebo_ros_pkgs.so" name="gazebo_ros_control">
      <robotNamespace>rover</robotNamespace>
    </plugin>
  </gazebo>
  <!-- LINKS -->
  <!-- TODO NO SUPPORT FOR CLOSED CHAINSD UNTIL URDF 2.0 TODO -->
  <!--xacro:include filename="rocker-bogie/differential.xacro"/-->
  <!--xacro:property name="h_bogie" value=".100"/-->
  <!--xacro:property name="l_bogie" value=".305"/-->
  <!--xacro:property name="l_wheel_m" value=".160"/>
    <xacro:property name="l_wheel_b" value=".160"/-->
  <!-- DUMMY LINK -->
  <link name="base_link">
        </link>
  <joint name="base_jonit" type="fixed">
    <parent link="base_link"/>
    <child link="suspension_beam"/>
  </joint>
  <!-- MAIN LINK -->
  <link name="suspension_beam">
    <visual>
      <origin rpy="1.57075 0 0" xyz="0 0 0"/>
      <geometry>
        <cylinder length="0.6" radius="0.025"/>
      </geometry>
      <material name="light_green">
        <color rgba=".6 .9 .6 1"/>
      </material>
    </visual>
    <collision>
      <origin rpy="1.57075 0 0" xyz="0 0 0"/>
      <geometry>
        <cylinder length="0.6" radius="0.025"/>
      </geometry>
    </collision>
    <inertial>
      <mass value="3"/>
      <inertia ixx="0.005" ixy="0" ixz="0" iyy="0.005" iyz="0" izz="0.005"/>
    </inertial>
  </link>
  <gazebo reference="suspension_beam">
    <mu1> .2 </mu1>
    <mu2> .2 </mu2>
    <material> Gazebo/Gray </material>
    <selfCollide> false </selfCollide>
  </gazebo>
  <link name="rocker_l_bearing">
    <visual>
      <origin rpy="1.57075 0 0"/>
      <geometry>
        <cylinder length="0.05" radius="0.035"/>
      </geometry>
      <material name="dark_green">
        <color rgba=".3 .5 .2 1"/>
      </material>
    </visual>
    <collision>
      <origin rpy="1.57075 0 0"/>
      <geometry>
        <cylinder length="0.05" radius="0.035"/>
      </geometry>
    </collision>
    <inertial>
      <mass value="3"/>
      <inertia ixx="0.005" ixy="0" ixz="0" iyy="0.005" iyz="0" izz="0.005"/>
    </inertial>
  </link>
  <!--joint name="${name}_joint" type="revolute">
                <parent link="${parent}"/>
                <child link="${name}"/>
                <origin rpy="0 0 0" xyz="${x} ${y} ${z}"/>
                <axis xyz="0 1 0"/>
                <limit effort="10000" velocity="1" lower="-0.5" upper="0.5"/>
                <dynamics damping="2" friction="0"/>
            </joint-->
  <joint name="rocker_l_bearing_joint" type="fixed">
    <parent link="suspension_beam"/>
    <child link="rocker_l_bearing"/>
    <origin rpy="0 0 0" xyz="0 0.3 0"/>
  </joint>
  <gazebo reference="rocker_l_bearing">
    <mu1> .2 </mu1>
    <mu2> .2 </mu2>
    <material> Gazebo/Gray </material>
    <selfCollide> False </selfCollide>
  </gazebo>
  <!--transmission name="${name}_transmission">
                <type>transmission_interface/SimpleTransmission</type>
                <joint name="${name}_joint">
                    <hardwareInterface>EffortJointInterface</hardwareInterface>
                </joint>
                <actuator name="${name}_motor">
                    <hardwareInterface>EffortJointInterface</hardwareInterface>
                    <mechanicalReduction>1</mechanicalReduction>
                </actuator>
            </transmission-->
  <link name="rocker_l_link_1">
    <visual>
      <origin rpy="0 0 0" xyz="0.05 0.0 0.0"/>
      <geometry>
        <box size="0.5 0.04 0.05"/>
      </geometry>
      <material name="light_blue">
        <color rgba=".3 .3 .6 1"/>
      </material>
    </visual>
    <visual>
      <origin rpy="1.57075 0 0" xyz="-0.2 0.0 0.0"/>
      <geometry>
        <cylinder length="0.04" radius="0.025"/>
      </geometry>
      <material name="light_blue">
        <color rgba=".3 .3 .6 1"/>
      </material>
    </visual>
    <visual>
      <origin rpy="1.57075 0 0" xyz="0.3 0.0 0.0"/>
      <geometry>
        <cylinder length="0.04" radius="0.025"/>
      </geometry>
      <material name="light_blue">
        <color rgba=".3 .3 .6 1"/>
      </material>
    </visual>
    <collision>
      <origin rpy="0 0 0" xyz="0.05 0.0 0.0"/>
      <geometry>
        <box size="0.5 0.04 0.05"/>
      </geometry>
    </collision>
    <collision>
      <origin rpy="1.57075 0 0" xyz="-0.2 0.0 0.0"/>
      <geometry>
        <cylinder length="0.04" radius="0.025"/>
      </geometry>
    </collision>
    <collision>
      <origin rpy="1.57075 0 0" xyz="0.3 0.0 0.0"/>
      <geometry>
        <cylinder length="0.04" radius="0.025"/>
      </geometry>
    </collision>
    <inertial>
      <origin rpy="0 0 0" xyz="0.05 0.0 0.0"/>
      <mass value="2"/>
      <inertia ixx=".003" ixy="0.000" ixz="0.000" iyy=".003" iyz="0.000" izz=".003"/>
    </inertial>
  </link>
  <gazebo reference="rocker_l_link_1">
    <mu1> .2 </mu1>
    <mu2> .2 </mu2>
    <material> Gazebo/Blue </material>
    <selfCollide>False</selfCollide>
  </gazebo>
  <joint name="rocker_l_link_1_joint" type="fixed">
    <parent link="rocker_l_bearing"/>
    <child link="rocker_l_link_1"/>
    <origin rpy="0 0.2 0" xyz="0.0 -0.0 0.0"/>
  </joint>
  <link name="rocker_l_link_2">
    <visual>
      <origin rpy="0 0 0" xyz="-0.125 0.0 0.0 "/>
      <geometry>
        <box size="0.25 0.04 0.05"/>
      </geometry>
      <material name="light_blue">
        <color rgba=".3 .3 .6 1"/>
      </material>
    </visual>
    x
            
    <collision>
      <origin rpy="0 0 0" xyz="-0.125 0.0 0.0 "/>
      <geometry>
        <box size="0.25 0.04 0.05"/>
      </geometry>
    </collision>
    <inertial>
      <origin rpy="0 0 0" xyz="-0.125 0.0 0.0"/>
      <mass value=".2"/>
      <inertia ixx=".003" ixy="0.000" ixz="0.000" iyy=".003" iyz="0.000" izz=".003"/>
    </inertial>
  </link>
  <gazebo reference="rocker_l_link_2">
    <mu1> .2 </mu1>
    <mu2> .2 </mu2>
    <material> Gazebo/Blue </material>
    <selfCollide>False</selfCollide>
  </gazebo>
  <joint name="rocker_l_link_2_joint" type="fixed">
    <parent link="rocker_l_link_1"/>
    <child link="rocker_l_link_2"/>
    <origin rpy="0 -1.28 0" xyz="-0.2 -0.0 0.0"/>
  </joint>
  <link name="rocker_l_link_3">
    <visual>
      <origin rpy="0 0 0" xyz="0.095 0.0 0.0 "/>
      <geometry>
        <box size="0.19 0.04 0.05"/>
      </geometry>
      <material name="light_blue">
        <color rgba=".3 .3 .6 1"/>
      </material>
    </visual>
    <visual>
      <origin rpy="1.57075 0 0" xyz="0.19 0.0 0.0"/>
      <geometry>
        <cylinder length="0.04" radius="0.025"/>
      </geometry>
      <material name="light_blue">
        <color rgba=".3 .3 .6 1"/>
      </material>
    </visual>
    <collision>
      <origin rpy="0 0 0" xyz="0.095 0.0 0.0 "/>
      <geometry>
        <box size="0.19 0.04 0.05"/>
      </geometry>
    </collision>
    <collision>
      <origin rpy="1.57075 0 0" xyz="0.19 0.0 0.0"/>
      <geometry>
        <cylinder length="0.04" radius="0.025"/>
      </geometry>
    </collision>
    <inertial>
      <origin rpy="0 0 0" xyz="0.095 0.0 0.0 "/>
      <mass value="2"/>
      <inertia ixx=".003" ixy="0.000" ixz="0.000" iyy=".003" iyz="0.000" izz=".003"/>
    </inertial>
  </link>
  <gazebo reference="rocker_l_link_3">
    <mu1> .2 </mu1>
    <mu2> .2 </mu2>
    <material> Gazebo/Blue </material>
    <selfCollide>False</selfCollide>
  </gazebo>
  <joint name="rocker_l_link_3_joint" type="fixed">
    <parent link="rocker_l_link_1"/>
    <child link="rocker_l_link_3"/>
    <origin rpy="0 1.31 0" xyz="0.3 -0.0 0.0"/>
  </joint>
  <!--xacro:link_diff name="${name}_link_diff" parent="${name}_bearing"  x="0" y="0" z="0"/-->
  <link name="rocker_r_bearing">
    <visual>
      <origin rpy="1.57075 0 0"/>
      <geometry>
        <cylinder length="0.05" radius="0.035"/>
      </geometry>
      <material name="dark_green">
        <color rgba=".3 .5 .2 1"/>
      </material>
    </visual>
    <collision>
      <origin rpy="1.57075 0 0"/>
      <geometry>
        <cylinder length="0.05" radius="0.035"/>
      </geometry>
    </collision>
    <inertial>
      <mass value="3"/>
      <inertia ixx="0.005" ixy="0" ixz="0" iyy="0.005" iyz="0" izz="0.005"/>
    </inertial>
  </link>
  <!--joint name="${name}_joint" type="revolute">
                <parent link="${parent}"/>
                <child link="${name}"/>
                <origin rpy="0 0 0" xyz="${x} ${y} ${z}"/>
                <axis xyz="0 1 0"/>
                <limit effort="10000" velocity="1" lower="-0.5" upper="0.5"/>
                <dynamics damping="2" friction="0"/>
            </joint-->
  <joint name="rocker_r_bearing_joint" type="fixed">
    <parent link="suspension_beam"/>
    <child link="rocker_r_bearing"/>
    <origin rpy="0 0 0" xyz="0 -0.3 0"/>
  </joint>
  <gazebo reference="rocker_r_bearing">
    <mu1> .2 </mu1>
    <mu2> .2 </mu2>
    <material> Gazebo/Gray </material>
    <selfCollide> False </selfCollide>
  </gazebo>
  <!--transmission name="${name}_transmission">
                <type>transmission_interface/SimpleTransmission</type>
                <joint name="${name}_joint">
                    <hardwareInterface>EffortJointInterface</hardwareInterface>
                </joint>
                <actuator name="${name}_motor">
                    <hardwareInterface>EffortJointInterface</hardwareInterface>
                    <mechanicalReduction>1</mechanicalReduction>
                </actuator>
            </transmission-->
  <link name="rocker_r_link_1">
    <visual>
      <origin rpy="0 0 0" xyz="0.05 0.0 0.0"/>
      <geometry>
        <box size="0.5 0.04 0.05"/>
      </geometry>
      <material name="light_blue">
        <color rgba=".3 .3 .6 1"/>
      </material>
    </visual>
    <visual>
      <origin rpy="1.57075 0 0" xyz="-0.2 0.0 0.0"/>
      <geometry>
        <cylinder length="0.04" radius="0.025"/>
      </geometry>
      <material name="light_blue">
        <color rgba=".3 .3 .6 1"/>
      </material>
    </visual>
    <visual>
      <origin rpy="1.57075 0 0" xyz="0.3 0.0 0.0"/>
      <geometry>
        <cylinder length="0.04" radius="0.025"/>
      </geometry>
      <material name="light_blue">
        <color rgba=".3 .3 .6 1"/>
      </material>
    </visual>
    <collision>
      <origin rpy="0 0 0" xyz="0.05 0.0 0.0"/>
      <geometry>
        <box size="0.5 0.04 0.05"/>
      </geometry>
    </collision>
    <collision>
      <origin rpy="1.57075 0 0" xyz="-0.2 0.0 0.0"/>
      <geometry>
        <cylinder length="0.04" radius="0.025"/>
      </geometry>
    </collision>
    <collision>
      <origin rpy="1.57075 0 0" xyz="0.3 0.0 0.0"/>
      <geometry>
        <cylinder length="0.04" radius="0.025"/>
      </geometry>
    </collision>
    <inertial>
      <origin rpy="0 0 0" xyz="0.05 0.0 0.0"/>
      <mass value="2"/>
      <inertia ixx=".003" ixy="0.000" ixz="0.000" iyy=".003" iyz="0.000" izz=".003"/>
    </inertial>
  </link>
  <gazebo reference="rocker_r_link_1">
    <mu1> .2 </mu1>
    <mu2> .2 </mu2>
    <material> Gazebo/Blue </material>
    <selfCollide>False</selfCollide>
  </gazebo>
  <joint name="rocker_r_link_1_joint" type="fixed">
    <parent link="rocker_r_bearing"/>
    <child link="rocker_r_link_1"/>
    <origin rpy="0 0.2 0" xyz="0.0 -0.0 0.0"/>
  </joint>
  <link name="rocker_r_link_2">
    <visual>
      <origin rpy="0 0 0" xyz="-0.125 0.0 0.0 "/>
      <geometry>
        <box size="0.25 0.04 0.05"/>
      </geometry>
      <material name="light_blue">
        <color rgba=".3 .3 .6 1"/>
      </material>
    </visual>
    x
            
    <collision>
      <origin rpy="0 0 0" xyz="-0.125 0.0 0.0 "/>
      <geometry>
        <box size="0.25 0.04 0.05"/>
      </geometry>
    </collision>
    <inertial>
      <origin rpy="0 0 0" xyz="-0.125 0.0 0.0"/>
      <mass value=".2"/>
      <inertia ixx=".003" ixy="0.000" ixz="0.000" iyy=".003" iyz="0.000" izz=".003"/>
    </inertial>
  </link>
  <gazebo reference="rocker_r_link_2">
    <mu1> .2 </mu1>
    <mu2> .2 </mu2>
    <material> Gazebo/Blue </material>
    <selfCollide>False</selfCollide>
  </gazebo>
  <joint name="rocker_r_link_2_joint" type="fixed">
    <parent link="rocker_r_link_1"/>
    <child link="rocker_r_link_2"/>
    <origin rpy="0 -1.28 0" xyz="-0.2 -0.0 0.0"/>
  </joint>
  <link name="rocker_r_link_3">
    <visual>
      <origin rpy="0 0 0" xyz="0.095 0.0 0.0 "/>
      <geometry>
        <box size="0.19 0.04 0.05"/>
      </geometry>
      <material name="light_blue">
        <color rgba=".3 .3 .6 1"/>
      </material>
    </visual>
    <visual>
      <origin rpy="1.57075 0 0" xyz="0.19 0.0 0.0"/>
      <geometry>
        <cylinder length="0.04" radius="0.025"/>
      </geometry>
      <material name="light_blue">
        <color rgba=".3 .3 .6 1"/>
      </material>
    </visual>
    <collision>
      <origin rpy="0 0 0" xyz="0.095 0.0 0.0 "/>
      <geometry>
        <box size="0.19 0.04 0.05"/>
      </geometry>
    </collision>
    <collision>
      <origin rpy="1.57075 0 0" xyz="0.19 0.0 0.0"/>
      <geometry>
        <cylinder length="0.04" radius="0.025"/>
      </geometry>
    </collision>
    <inertial>
      <origin rpy="0 0 0" xyz="0.095 0.0 0.0 "/>
      <mass value="2"/>
      <inertia ixx=".003" ixy="0.000" ixz="0.000" iyy=".003" iyz="0.000" izz=".003"/>
    </inertial>
  </link>
  <gazebo reference="rocker_r_link_3">
    <mu1> .2 </mu1>
    <mu2> .2 </mu2>
    <material> Gazebo/Blue </material>
    <selfCollide>False</selfCollide>
  </gazebo>
  <joint name="rocker_r_link_3_joint" type="fixed">
    <parent link="rocker_r_link_1"/>
    <child link="rocker_r_link_3"/>
    <origin rpy="0 1.31 0" xyz="0.3 -0.0 0.0"/>
  </joint>
  <!--xacro:link_diff name="${name}_link_diff" parent="${name}_bearing"  x="0" y="0" z="0"/-->
  <link name="bogie_l_bearing">
    <visual>
      <origin rpy="1.57075 0 0"/>
      <geometry>
        <cylinder length="0.1" radius="0.03"/>
      </geometry>
      <material name="dark_green">
        <color rgba=".3 .5 .2 1"/>
      </material>
    </visual>
    <collision>
      <origin rpy="1.57075 0 0"/>
      <geometry>
        <cylinder length="0.1" radius="0.03"/>
      </geometry>
    </collision>
    <inertial>
      <mass value="3"/>
      <inertia ixx="0.005" ixy="0" ixz="0" iyy="0.005" iyz="0" izz="0.005"/>
    </inertial>
  </link>
  <joint name="bogie_l_bearing_joint" type="revolute">
    <parent link="rocker_l_bearing"/>
    <child link="bogie_l_bearing"/>
    <origin rpy="0 0 0" xyz="-0.305 0 -0.17"/>
    <axis xyz="0 1 0"/>
    <limit effort="1" lower="-0.5" upper="0.5" velocity="1"/>
    <dynamics damping="1"/>
  </joint>
  <gazebo reference="bogie_l_bearing">
    <mu1> .2 </mu1>
    <mu2> .2 </mu2>
    <material> Gazebo/Gray </material>
    <selfCollide> False </selfCollide>
  </gazebo>
  <transmission name="bogie_l_bearing_transmission">
    <type>transmission_interface/SimpleTransmission</type>
    <joint name="bogie_l_bearing_joint">
      <hardwareInterface>EffortJointInterface</hardwareInterface>
    </joint>
    <actuator name="bogie_l_bearing_motor">
      <hardwareInterface>EffortJointInterface</hardwareInterface>
      <mechanicalReduction>1</mechanicalReduction>
    </actuator>
  </transmission>
  <link name="bogie_l_link_1">
    <visual>
      <origin rpy="0 0 0" xyz="0.1075 0.025 0.0"/>
      <geometry>
        <box size="0.215 0.04 0.05"/>
      </geometry>
      <material name="light_blue">
        <color rgba=".3 .3 .6 1"/>
      </material>
    </visual>
    <visual>
      <origin rpy="1.57075 0 0" xyz="0.215 0.025 0.0"/>
      <geometry>
        <cylinder length="0.04" radius="0.025"/>
      </geometry>
      <material name="light_blue">
        <color rgba=".3 .3 .6 1"/>
      </material>
    </visual>
    <collision>
      <origin rpy="0 0 0" xyz="0.1075 0.025 0.0"/>
      <geometry>
        <box size="0.215 0.04 0.05"/>
      </geometry>
    </collision>
    <collision>
      <origin rpy="1.57075 0 0" xyz="0.215 0.025 0.0"/>
      <geometry>
        <cylinder length="0.04" radius="0.025"/>
      </geometry>
    </collision>
    <inertial>
      <origin rpy="0 0 0" xyz="0.1075 0.025 0.0"/>
      <mass value="2"/>
      <inertia ixx=".003" ixy="0.000" ixz="0.000" iyy=".003" iyz="0.000" izz=".003"/>
    </inertial>
  </link>
  <gazebo reference="bogie_l_link_1">
    <mu1> .2 </mu1>
    <mu2> .2 </mu2>
    <material> Gazebo/Blue </material>
    <selfCollide>False</selfCollide>
  </gazebo>
  <joint name="bogie_l_link_1_joint" type="fixed">
    <parent link="bogie_l_bearing"/>
    <child link="bogie_l_link_1"/>
    <origin rpy="0 0.38 0" xyz="0.0 -0.0 0.0"/>
  </joint>
  <link name="bogie_l_link_2">
    <visual>
      <origin rpy="0 0 0" xyz="-0.1075 -0.025 0.0"/>
      <geometry>
        <box size="0.215 0.04 0.05"/>
      </geometry>
      <material name="light_blue">
        <color rgba=".3 .3 .6 1"/>
      </material>
    </visual>
    <visual>
      <origin rpy="1.57075 0 0" xyz="-0.215 -0.025 0.0"/>
      <geometry>
        <cylinder length="0.04" radius="0.025"/>
      </geometry>
      <material name="light_blue">
        <color rgba=".3 .3 .6 1"/>
      </material>
    </visual>
    <collision>
      <origin rpy="0 0 0" xyz="-0.1075 -0.025 0.0"/>
      <geometry>
        <box size="0.215 0.04 0.05"/>
      </geometry>
    </collision>
    <collision>
      <origin rpy="1.57075 0 0" xyz="-0.215 -0.025 0.0"/>
      <geometry>
        <cylinder length="0.04" radius="0.025"/>
      </geometry>
    </collision>
    <inertial>
      <origin rpy="0 0 0" xyz="-0.1075 -0.025 0.0"/>
      <mass value="2"/>
      <inertia ixx=".003" ixy="0.000" ixz="0.000" iyy=".003" iyz="0.000" izz=".003"/>
    </inertial>
  </link>
  <gazebo reference="bogie_l_link_2">
    <mu1> .2 </mu1>
    <mu2> .2 </mu2>
    <material> Gazebo/Blue </material>
    <selfCollide>False</selfCollide>
  </gazebo>
  <joint name="bogie_l_link_2_joint" type="fixed">
    <parent link="bogie_l_bearing"/>
    <child link="bogie_l_link_2"/>
    <origin rpy="0 -0.38 0" xyz="0.0 -0.0 0.0"/>
  </joint>
  <link name="bogie_r_bearing">
    <visual>
      <origin rpy="1.57075 0 0"/>
      <geometry>
        <cylinder length="0.1" radius="0.03"/>
      </geometry>
      <material name="dark_green">
        <color rgba=".3 .5 .2 1"/>
      </material>
    </visual>
    <collision>
      <origin rpy="1.57075 0 0"/>
      <geometry>
        <cylinder length="0.1" radius="0.03"/>
      </geometry>
    </collision>
    <inertial>
      <mass value="3"/>
      <inertia ixx="0.005" ixy="0" ixz="0" iyy="0.005" iyz="0" izz="0.005"/>
    </inertial>
  </link>
  <joint name="bogie_r_bearing_joint" type="revolute">
    <parent link="rocker_r_bearing"/>
    <child link="bogie_r_bearing"/>
    <origin rpy="0 0 0" xyz="-0.305 0 -0.17"/>
    <axis xyz="0 1 0"/>
    <limit effort="1" lower="-0.5" upper="0.5" velocity="1"/>
    <dynamics damping="1"/>
  </joint>
  <gazebo reference="bogie_r_bearing">
    <mu1> .2 </mu1>
    <mu2> .2 </mu2>
    <material> Gazebo/Gray </material>
    <selfCollide> False </selfCollide>
  </gazebo>
  <transmission name="bogie_r_bearing_transmission">
    <type>transmission_interface/SimpleTransmission</type>
    <joint name="bogie_r_bearing_joint">
      <hardwareInterface>EffortJointInterface</hardwareInterface>
    </joint>
    <actuator name="bogie_r_bearing_motor">
      <hardwareInterface>EffortJointInterface</hardwareInterface>
      <mechanicalReduction>1</mechanicalReduction>
    </actuator>
  </transmission>
  <link name="bogie_r_link_1">
    <visual>
      <origin rpy="0 0 0" xyz="0.1075 -0.025 0.0"/>
      <geometry>
        <box size="0.215 0.04 0.05"/>
      </geometry>
      <material name="light_blue">
        <color rgba=".3 .3 .6 1"/>
      </material>
    </visual>
    <visual>
      <origin rpy="1.57075 0 0" xyz="0.215 -0.025 0.0"/>
      <geometry>
        <cylinder length="0.04" radius="0.025"/>
      </geometry>
      <material name="light_blue">
        <color rgba=".3 .3 .6 1"/>
      </material>
    </visual>
    <collision>
      <origin rpy="0 0 0" xyz="0.1075 -0.025 0.0"/>
      <geometry>
        <box size="0.215 0.04 0.05"/>
      </geometry>
    </collision>
    <collision>
      <origin rpy="1.57075 0 0" xyz="0.215 -0.025 0.0"/>
      <geometry>
        <cylinder length="0.04" radius="0.025"/>
      </geometry>
    </collision>
    <inertial>
      <origin rpy="0 0 0" xyz="0.1075 -0.025 0.0"/>
      <mass value="2"/>
      <inertia ixx=".003" ixy="0.000" ixz="0.000" iyy=".003" iyz="0.000" izz=".003"/>
    </inertial>
  </link>
  <gazebo reference="bogie_r_link_1">
    <mu1> .2 </mu1>
    <mu2> .2 </mu2>
    <material> Gazebo/Blue </material>
    <selfCollide>False</selfCollide>
  </gazebo>
  <joint name="bogie_r_link_1_joint" type="fixed">
    <parent link="bogie_r_bearing"/>
    <child link="bogie_r_link_1"/>
    <origin rpy="0 0.38 0" xyz="0.0 -0.0 0.0"/>
  </joint>
  <link name="bogie_r_link_2">
    <visual>
      <origin rpy="0 0 0" xyz="-0.1075 0.025 0.0"/>
      <geometry>
        <box size="0.215 0.04 0.05"/>
      </geometry>
      <material name="light_blue">
        <color rgba=".3 .3 .6 1"/>
      </material>
    </visual>
    <visual>
      <origin rpy="1.57075 0 0" xyz="-0.215 0.025 0.0"/>
      <geometry>
        <cylinder length="0.04" radius="0.025"/>
      </geometry>
      <material name="light_blue">
        <color rgba=".3 .3 .6 1"/>
      </material>
    </visual>
    <collision>
      <origin rpy="0 0 0" xyz="-0.1075 0.025 0.0"/>
      <geometry>
        <box size="0.215 0.04 0.05"/>
      </geometry>
    </collision>
    <collision>
      <origin rpy="1.57075 0 0" xyz="-0.215 0.025 0.0"/>
      <geometry>
        <cylinder length="0.04" radius="0.025"/>
      </geometry>
    </collision>
    <inertial>
      <origin rpy="0 0 0" xyz="-0.1075 0.025 0.0"/>
      <mass value="2"/>
      <inertia ixx=".003" ixy="0.000" ixz="0.000" iyy=".003" iyz="0.000" izz=".003"/>
    </inertial>
  </link>
  <gazebo reference="bogie_r_link_2">
    <mu1> .2 </mu1>
    <mu2> .2 </mu2>
    <material> Gazebo/Blue </material>
    <selfCollide>False</selfCollide>
  </gazebo>
  <joint name="bogie_r_link_2_joint" type="fixed">
    <parent link="bogie_r_bearing"/>
    <child link="bogie_r_link_2"/>
    <origin rpy="0 -0.38 0" xyz="0.0 -0.0 0.0"/>
  </joint>
  <!-- WHEELS -->
  <link name="wheel_fl">
    <visual>
      <origin rpy="1.57075 0 0"/>
      <geometry>
        <cylinder length="0.1" radius="0.1"/>
      </geometry>
      <material name="black">
        <color rgba=".0 .0 .0 1"/>
      </material>
    </visual>
    <collision>
      <origin rpy="1.57075 0 0"/>
      <geometry>
        <cylinder length="0.1" radius="0.1"/>
      </geometry>
    </collision>
    <inertial>
      <mass value="3"/>
      <inertia ixx=".03" ixy="0.000" ixz="0.000" iyy=".03" iyz="0.000" izz=".03"/>
    </inertial>
  </link>
  <joint name="wheel_fl_joint" type="continuous">
    <parent link="rocker_l_bearing"/>
    <child link="wheel_fl"/>
    <origin rpy="0 0 0" xyz="0.305 0.075 -0.25"/>
    <axis xyz="0 1 0"/>
    <limit effort="100" velocity="10"/>
    <dynamics damping="1"/>
  </joint>
  <gazebo reference="wheel_fl">
    <mu1> 1 </mu1>
    <mu2> 1 </mu2>
    <!--fdir1> 0 1 0 </fdir1-->
    <material> Gazebo/Black </material>
    <selfCollide> true </selfCollide>
  </gazebo>
  <gazebo>
    <plugin filename="libJointLimiter.so" name="wheel_fl_joint_limiter">
      <joint>wheel_fl_joint</joint>
      <topic>/rover/wheel_fl_velocity_controller</topic>
      <lower>-9999999</lower>
      <upper>9999999</upper>
    </plugin>
  </gazebo>
  <gazebo>
    <plugin filename="libControllerPID.so" name="wheel_fl_controller">
      <joint>wheel_fl_joint</joint>
      <topic>/rover/wheel_fl_velocity_controller</topic>
      <Kp>5</Kp>
      <Ki>0.5</Ki>
      <Kd>0.4</Kd>
      <limit>100</limit>
    </plugin>
  </gazebo>
  <!--transmission name="${name}_transmission">
            <type>transmission_interface/SimpleTransmission</type>
            <joint name="${name}_wheel_joint">
                <hardwareInterface>EffortJointInterface</hardwareInterface>
            </joint>
            <actuator name="${name}_wheel_motor">
                <hardwareInterface>EffortJointInterface</hardwareInterface>
                <mechanicalReduction>1</mechanicalReduction>
            </actuator>
        </transmission-->
  <link name="wheel_fr">
    <visual>
      <origin rpy="1.57075 0 0"/>
      <geometry>
        <cylinder length="0.1" radius="0.1"/>
      </geometry>
      <material name="black">
        <color rgba=".0 .0 .0 1"/>
      </material>
    </visual>
    <collision>
      <origin rpy="1.57075 0 0"/>
      <geometry>
        <cylinder length="0.1" radius="0.1"/>
      </geometry>
    </collision>
    <inertial>
      <mass value="3"/>
      <inertia ixx=".03" ixy="0.000" ixz="0.000" iyy=".03" iyz="0.000" izz=".03"/>
    </inertial>
  </link>
  <joint name="wheel_fr_joint" type="continuous">
    <parent link="rocker_r_bearing"/>
    <child link="wheel_fr"/>
    <origin rpy="0 0 0" xyz="0.305 -0.075 -0.25"/>
    <axis xyz="0 1 0"/>
    <limit effort="100" velocity="10"/>
    <dynamics damping="1"/>
  </joint>
  <gazebo reference="wheel_fr">
    <mu1> 1 </mu1>
    <mu2> 1 </mu2>
    <!--fdir1> 0 1 0 </fdir1-->
    <material> Gazebo/Black </material>
    <selfCollide> true </selfCollide>
  </gazebo>
  <gazebo>
    <plugin filename="libJointLimiter.so" name="wheel_fr_joint_limiter">
      <joint>wheel_fr_joint</joint>
      <topic>/rover/wheel_fr_velocity_controller</topic>
      <lower>-9999999</lower>
      <upper>9999999</upper>
    </plugin>
  </gazebo>
  <gazebo>
    <plugin filename="libControllerPID.so" name="wheel_fr_controller">
      <joint>wheel_fr_joint</joint>
      <topic>/rover/wheel_fr_velocity_controller</topic>
      <Kp>5</Kp>
      <Ki>0.5</Ki>
      <Kd>0.4</Kd>
      <limit>100</limit>
    </plugin>
  </gazebo>
  <!--transmission name="${name}_transmission">
            <type>transmission_interface/SimpleTransmission</type>
            <joint name="${name}_wheel_joint">
                <hardwareInterface>EffortJointInterface</hardwareInterface>
            </joint>
            <actuator name="${name}_wheel_motor">
                <hardwareInterface>EffortJointInterface</hardwareInterface>
                <mechanicalReduction>1</mechanicalReduction>
            </actuator>
        </transmission-->
  <link name="wheel_ml">
    <visual>
      <origin rpy="1.57075 0 0"/>
      <geometry>
        <cylinder length="0.1" radius="0.1"/>
      </geometry>
      <material name="black">
        <color rgba=".0 .0 .0 1"/>
      </material>
    </visual>
    <collision>
      <origin rpy="1.57075 0 0"/>
      <geometry>
        <cylinder length="0.1" radius="0.1"/>
      </geometry>
    </collision>
    <inertial>
      <mass value="3"/>
      <inertia ixx=".03" ixy="0.000" ixz="0.000" iyy=".03" iyz="0.000" izz=".03"/>
    </inertial>
  </link>
  <joint name="wheel_ml_joint" type="continuous">
    <parent link="bogie_l_bearing"/>
    <child link="wheel_ml"/>
    <origin rpy="0 0 0" xyz="0.2 0.1 -0.08"/>
    <axis xyz="0 1 0"/>
    <limit effort="100" velocity="10"/>
    <dynamics damping="1"/>
  </joint>
  <gazebo reference="wheel_ml">
    <mu1> 1 </mu1>
    <mu2> 1 </mu2>
    <!--fdir1> 0 1 0 </fdir1-->
    <material> Gazebo/Black </material>
    <selfCollide> true </selfCollide>
  </gazebo>
  <gazebo>
    <plugin filename="libJointLimiter.so" name="wheel_ml_joint_limiter">
      <joint>wheel_ml_joint</joint>
      <topic>/rover/wheel_ml_velocity_controller</topic>
      <lower>-9999999</lower>
      <upper>9999999</upper>
    </plugin>
  </gazebo>
  <gazebo>
    <plugin filename="libControllerPID.so" name="wheel_ml_controller">
      <joint>wheel_ml_joint</joint>
      <topic>/rover/wheel_ml_velocity_controller</topic>
      <Kp>5</Kp>
      <Ki>0.5</Ki>
      <Kd>0.4</Kd>
      <limit>100</limit>
    </plugin>
  </gazebo>
  <!--transmission name="${name}_transmission">
            <type>transmission_interface/SimpleTransmission</type>
            <joint name="${name}_wheel_joint">
                <hardwareInterface>EffortJointInterface</hardwareInterface>
            </joint>
            <actuator name="${name}_wheel_motor">
                <hardwareInterface>EffortJointInterface</hardwareInterface>
                <mechanicalReduction>1</mechanicalReduction>
            </actuator>
        </transmission-->
  <link name="wheel_mr">
    <visual>
      <origin rpy="1.57075 0 0"/>
      <geometry>
        <cylinder length="0.1" radius="0.1"/>
      </geometry>
      <material name="black">
        <color rgba=".0 .0 .0 1"/>
      </material>
    </visual>
    <collision>
      <origin rpy="1.57075 0 0"/>
      <geometry>
        <cylinder length="0.1" radius="0.1"/>
      </geometry>
    </collision>
    <inertial>
      <mass value="3"/>
      <inertia ixx=".03" ixy="0.000" ixz="0.000" iyy=".03" iyz="0.000" izz=".03"/>
    </inertial>
  </link>
  <joint name="wheel_mr_joint" type="continuous">
    <parent link="bogie_r_bearing"/>
    <child link="wheel_mr"/>
    <origin rpy="0 0 0" xyz="0.2 -0.1 -0.08"/>
    <axis xyz="0 1 0"/>
    <limit effort="100" velocity="10"/>
    <dynamics damping="1"/>
  </joint>
  <gazebo reference="wheel_mr">
    <mu1> 1 </mu1>
    <mu2> 1 </mu2>
    <!--fdir1> 0 1 0 </fdir1-->
    <material> Gazebo/Black </material>
    <selfCollide> true </selfCollide>
  </gazebo>
  <gazebo>
    <plugin filename="libJointLimiter.so" name="wheel_mr_joint_limiter">
      <joint>wheel_mr_joint</joint>
      <topic>/rover/wheel_mr_velocity_controller</topic>
      <lower>-9999999</lower>
      <upper>9999999</upper>
    </plugin>
  </gazebo>
  <gazebo>
    <plugin filename="libControllerPID.so" name="wheel_mr_controller">
      <joint>wheel_mr_joint</joint>
      <topic>/rover/wheel_mr_velocity_controller</topic>
      <Kp>5</Kp>
      <Ki>0.5</Ki>
      <Kd>0.4</Kd>
      <limit>100</limit>
    </plugin>
  </gazebo>
  <!--transmission name="${name}_transmission">
            <type>transmission_interface/SimpleTransmission</type>
            <joint name="${name}_wheel_joint">
                <hardwareInterface>EffortJointInterface</hardwareInterface>
            </joint>
            <actuator name="${name}_wheel_motor">
                <hardwareInterface>EffortJointInterface</hardwareInterface>
                <mechanicalReduction>1</mechanicalReduction>
            </actuator>
        </transmission-->
  <link name="wheel_bl">
    <visual>
      <origin rpy="1.57075 0 0"/>
      <geometry>
        <cylinder length="0.1" radius="0.1"/>
      </geometry>
      <material name="black">
        <color rgba=".0 .0 .0 1"/>
      </material>
    </visual>
    <collision>
      <origin rpy="1.57075 0 0"/>
      <geometry>
        <cylinder length="0.1" radius="0.1"/>
      </geometry>
    </collision>
    <inertial>
      <mass value="3"/>
      <inertia ixx=".03" ixy="0.000" ixz="0.000" iyy=".03" iyz="0.000" izz=".03"/>
    </inertial>
  </link>
  <joint name="wheel_bl_joint" type="continuous">
    <parent link="bogie_l_bearing"/>
    <child link="wheel_bl"/>
    <origin rpy="0 0 0" xyz="-0.2 0.05 -0.08"/>
    <axis xyz="0 1 0"/>
    <limit effort="100" velocity="10"/>
    <dynamics damping="1"/>
  </joint>
  <gazebo reference="wheel_bl">
    <mu1> 1 </mu1>
    <mu2> 1 </mu2>
    <!--fdir1> 0 1 0 </fdir1-->
    <material> Gazebo/Black </material>
    <selfCollide> true </selfCollide>
  </gazebo>
  <gazebo>
    <plugin filename="libJointLimiter.so" name="wheel_bl_joint_limiter">
      <joint>wheel_bl_joint</joint>
      <topic>/rover/wheel_bl_velocity_controller</topic>
      <lower>-9999999</lower>
      <upper>9999999</upper>
    </plugin>
  </gazebo>
  <gazebo>
    <plugin filename="libControllerPID.so" name="wheel_bl_controller">
      <joint>wheel_bl_joint</joint>
      <topic>/rover/wheel_bl_velocity_controller</topic>
      <Kp>5</Kp>
      <Ki>0.5</Ki>
      <Kd>0.4</Kd>
      <limit>100</limit>
    </plugin>
  </gazebo>
  <!--transmission name="${name}_transmission">
            <type>transmission_interface/SimpleTransmission</type>
            <joint name="${name}_wheel_joint">
                <hardwareInterface>EffortJointInterface</hardwareInterface>
            </joint>
            <actuator name="${name}_wheel_motor">
                <hardwareInterface>EffortJointInterface</hardwareInterface>
                <mechanicalReduction>1</mechanicalReduction>
            </actuator>
        </transmission-->
  <link name="wheel_br">
    <visual>
      <origin rpy="1.57075 0 0"/>
      <geometry>
        <cylinder length="0.1" radius="0.1"/>
      </geometry>
      <material name="black">
        <color rgba=".0 .0 .0 1"/>
      </material>
    </visual>
    <collision>
      <origin rpy="1.57075 0 0"/>
      <geometry>
        <cylinder length="0.1" radius="0.1"/>
      </geometry>
    </collision>
    <inertial>
      <mass value="3"/>
      <inertia ixx=".03" ixy="0.000" ixz="0.000" iyy=".03" iyz="0.000" izz=".03"/>
    </inertial>
  </link>
  <joint name="wheel_br_joint" type="continuous">
    <parent link="bogie_r_bearing"/>
    <child link="wheel_br"/>
    <origin rpy="0 0 0" xyz="-0.2 -0.05 -0.08"/>
    <axis xyz="0 1 0"/>
    <limit effort="100" velocity="10"/>
    <dynamics damping="1"/>
  </joint>
  <gazebo reference="wheel_br">
    <mu1> 1 </mu1>
    <mu2> 1 </mu2>
    <!--fdir1> 0 1 0 </fdir1-->
    <material> Gazebo/Black </material>
    <selfCollide> true </selfCollide>
  </gazebo>
  <gazebo>
    <plugin filename="libJointLimiter.so" name="wheel_br_joint_limiter">
      <joint>wheel_br_joint</joint>
      <topic>/rover/wheel_br_velocity_controller</topic>
      <lower>-9999999</lower>
      <upper>9999999</upper>
    </plugin>
  </gazebo>
  <gazebo>
    <plugin filename="libControllerPID.so" name="wheel_br_controller">
      <joint>wheel_br_joint</joint>
      <topic>/rover/wheel_br_velocity_controller</topic>
      <Kp>5</Kp>
      <Ki>0.5</Ki>
      <Kd>0.4</Kd>
      <limit>100</limit>
    </plugin>
  </gazebo>
  <!--transmission name="${name}_transmission">
            <type>transmission_interface/SimpleTransmission</type>
            <joint name="${name}_wheel_joint">
                <hardwareInterface>EffortJointInterface</hardwareInterface>
            </joint>
            <actuator name="${name}_wheel_motor">
                <hardwareInterface>EffortJointInterface</hardwareInterface>
                <mechanicalReduction>1</mechanicalReduction>
            </actuator>
        </transmission-->
  <!-- MY DIFFERENTIAL PLUGIN -->
  <!--gazebo>
        <plugin name="differential" filename="libDifferential.so">
            <leftJoint>rocker_l_bearing_joint</leftJoint>
            <rightJoint>rocker_r_bearing_joint</rightJoint>
        </plugin>
    </gazebo-->
  <!--gazebo>
        <plugin name="differential_pid" filename="libDifferentialPID.so">
            <leftJoint>rocker_l_bearing_joint</leftJoint>
            <rightJoint>rocker_r_bearing_joint</rightJoint>
            <topic>/rover/differential_pid</topic>
            <Kp>0</Kp>
            <Ki>0</Ki>
            <Kd>0</Kd>
            <limit>10000</limit>
        </plugin>
    </gazebo-->
  <!-- PROPERTIES -->
  <!-- MAIN LINK -->
  <link name="main_body">
    <visual>
      <origin rpy="0 0 0" xyz="-0.08 0 -0.04"/>
      <geometry>
        <box size="0.7 0.4 0.15"/>
      </geometry>
      <material name="dark_gray">
        <color rgba=".2 .2 .3 1"/>
      </material>
    </visual>
    <collision>
      <origin rpy="0 0 0" xyz="-0.08 0 -0.04"/>
      <geometry>
        <box size="0.7 0.4 0.15"/>
      </geometry>
    </collision>
    <!-- BOXES FOR STONES -->
    <visual>
      <origin rpy="0 0 0" xyz="0.145 0 0.045"/>
      <geometry>
        <box size=".250 0.4 .100"/>
      </geometry>
      <material name="dark_gray">
        <color rgba=".2 .2 .3 1"/>
      </material>
    </visual>
    <collision>
      <origin rpy="0 0 0" xyz="0.145 0 0.045"/>
      <geometry>
        <box size=".250 0.4 .100"/>
      </geometry>
    </collision>
    <visual>
      <origin rpy="0 0 0" xyz="-0.38 0 0.045"/>
      <geometry>
        <box size=".100 0.4 .100"/>
      </geometry>
      <material name="dark_gray">
        <color rgba=".2 .2 .3 1"/>
      </material>
    </visual>
    <collision>
      <origin rpy="0 0 0" xyz="-0.38 0 0.045"/>
      <geometry>
        <box size=".100 0.4 .100"/>
      </geometry>
    </collision>
    <visual>
      <!-- dlugosc przergody - 150 mm -->
      <origin rpy="0 0 0" xyz="-0.155 0 0.045"/>
      <geometry>
        <box size=".050 0.4 .100"/>
      </geometry>
      <material name="dark_gray">
        <color rgba=".2 .2 .3 1"/>
      </material>
    </visual>
    <collision>
      <!-- dlugosc przergody - 150 mm -->
      <origin rpy="0 0 0" xyz="-0.155 0 0.045"/>
      <geometry>
        <box size=".050 0.4 .100"/>
      </geometry>
    </collision>
    <visual>
      <origin rpy="0 0 0" xyz="-0.08 0.175 0.045"/>
      <geometry>
        <box size="0.7 .050 .100"/>
      </geometry>
      <material name="dark_gray">
        <color rgba=".2 .2 .3 1"/>
      </material>
    </visual>
    <collision>
      <origin rpy="0 0 0" xyz="-0.08 0.175 0.045"/>
      <geometry>
        <box size="0.7 .050 .100"/>
      </geometry>
    </collision>
    <visual>
      <origin rpy="0 0 0" xyz="-0.08 0.0 0.045"/>
      <geometry>
        <box size="0.7 .050 .100"/>
      </geometry>
      <material name="dark_gray">
        <color rgba=".2 .2 .3 1"/>
      </material>
    </visual>
    <collision>
      <origin rpy="0 0 0" xyz="-0.08 0.0 0.045"/>
      <geometry>
        <box size="0.7 .050 .100"/>
      </geometry>
    </collision>
    <visual>
      <origin rpy="0 0 0" xyz="-0.08 -0.175 0.045"/>
      <geometry>
        <box size="0.7 .050 .100"/>
      </geometry>
      <material name="dark_gray">
        <color rgba=".2 .2 .3 1"/>
      </material>
    </visual>
    <collision>
      <origin rpy="0 0 0" xyz="-0.08 -0.175 0.045"/>
      <geometry>
        <box size="0.7 .050 .100"/>
      </geometry>
    </collision>
    <inertial>
      <origin rpy="0 0 0" xyz="0 0 -.2"/>
      <mass value="40"/>
      <inertia ixx=".1" ixy="0.001" ixz="0.001" iyy=".1" iyz="0.001" izz=".1"/>
    </inertial>
  </link>
  <gazebo reference="main_body">
    <mu1> .2 </mu1>
    <mu2> .2 </mu2>
    <material> Gazebo/Gray</material>
    <selfCollide> true </selfCollide>
  </gazebo>
  <joint name="main_body_joint" type="fixed">
    <parent link="suspension_beam"/>
    <child link="main_body"/>
    <origin rpy="0 0 0" xyz="0 0 0"/>
    <!--axis xyz="0 1 0"/>
            <limit effort="100" velocity="1" lower="-.4" upper=".4"/>
            <dynamics damping="999" friction="999"/-->
  </joint>
  <gazebo reference="main_body_joint">
    <stopCfm>0.8</stopCfm>
    <stopErp>0.5</stopErp>
    <provideFeedback>true</provideFeedback>
    <implicitSpringDamper>true</implicitSpringDamper>
    <fudgeFactor>0.0</fudgeFactor>
  </gazebo>
  <link name="tower_yaw">
    <visual>
      <geometry>
        <cylinder length="0.4" radius="0.025"/>
      </geometry>
      <material name="dark_gray"/>
    </visual>
    <collision>
      <geometry>
        <cylinder length="0.4" radius="0.025"/>
      </geometry>
    </collision>
    <inertial>
      <mass value="1"/>
      <inertia ixx="0.001" ixy="0" ixz="0" iyy="0.001" iyz="0" izz="0.01"/>
    </inertial>
  </link>
  <joint name="tower_yaw_joint" type="revolute">
    <parent link="main_body"/>
    <child link="tower_yaw"/>
    <origin rpy="0 0 0" xyz="-0.4 0.16 0.275"/>
    <axis xyz="0 0 -1"/>
    <limit effort="100" lower="-3.14" upper="3.14" velocity="10"/>
    <dynamics damping="1"/>
  </joint>
  <gazebo reference="tower_yaw">
    <mu1> .2 </mu1>
    <mu2> .2 </mu2>
    <material> Gazebo/Gray </material>
    <selfCollide> true </selfCollide>
  </gazebo>
  <gazebo>
    <plugin filename="libJointLimiter.so" name="tower_yaw_joint_limiter">
      <joint>tower_yaw_joint</joint>
      <topic>/rover/tower_yaw_velocity_controller</topic>
      <lower>-3.14</lower>
      <upper>3.14</upper>
    </plugin>
  </gazebo>
  <gazebo>
    <plugin filename="libControllerPID.so" name="tower_yaw_controller">
      <joint>tower_yaw_joint</joint>
      <topic>/rover/tower_yaw_velocity_controller</topic>
      <Kp>1</Kp>
      <Ki>0.7</Ki>
      <Kd>0.4</Kd>
    </plugin>
  </gazebo>
  <!--transmission name="${name}_transmission">
                <type>transmission_interface/SimpleTransmission</type>
                <joint name="${name}_joint">
                    <hardwareInterface>EffortJointInterface</hardwareInterface>
                </joint>
                <actuator name="${name}_motor">
                    <hardwareInterface>EffortJointInterface</hardwareInterface>
                    <mechanicalReduction>1</mechanicalReduction>
                </actuator>
            </transmission-->
  <link name="tower_pitch">
    <visual>
      <geometry>
        <box size="0.1 0.15 0.05"/>
      </geometry>
      <material name="light_gray">
        <color rgba=".3 .3 .5 1"/>
      </material>
    </visual>
    <collision>
      <geometry>
        <box size="0.1 0.15 0.05"/>
      </geometry>
    </collision>
    <inertial>
      <mass value="1"/>
      <inertia ixx="0.001" ixy="0" ixz="0" iyy="0.001" iyz="0" izz="0.001"/>
    </inertial>
  </link>
  <joint name="tower_pitch_joint" type="revolute">
    <parent link="tower_yaw"/>
    <child link="tower_pitch"/>
    <origin rpy="0 0 0" xyz="0 0 0.2"/>
    <axis xyz="0 1 0"/>
    <limit effort="100" lower="-0.785" upper="0.785" velocity="10"/>
    <dynamics damping="1"/>
  </joint>
  <gazebo reference="tower_pitch">
    <mu1> .2 </mu1>
    <mu2> .2 </mu2>
    <material> Gazebo/Yellow </material>
    <selfCollide> true </selfCollide>
  </gazebo>
  <gazebo>
    <plugin filename="libJointLimiter.so" name="tower_pitch_joint_limiter">
      <joint>tower_pitch_joint</joint>
      <topic>/rover/tower_pitch_velocity_controller</topic>
      <lower>-0.785</lower>
      <upper>0.785</upper>
    </plugin>
  </gazebo>
  <gazebo>
    <plugin filename="libControllerPID.so" name="tower_pitch_controller">
      <joint>tower_pitch_joint</joint>
      <topic>/rover/tower_pitch_velocity_controller</topic>
      <Kp>0.8</Kp>
      <Ki>0.25</Ki>
      <Kd>0.1</Kd>
    </plugin>
  </gazebo>
  <!--transmission name="${name}_transmission">
                <type>transmission_interface/SimpleTransmission</type>
                <joint name="${name}_joint">
                    <hardwareInterface>EffortJointInterface</hardwareInterface>
                </joint>
                <actuator name="${name}_motor">
                    <hardwareInterface>EffortJointInterface</hardwareInterface>
                    <mechanicalReduction>1</mechanicalReduction>
                </actuator>
            </transmission-->
  <!--CAMERA BOARD -->
  <link name="camera1">
    <visual>
      <origin rpy="0 0 0" xyz="0 0 0"/>
      <geometry>
        <box size="0.02 0.05 0.05"/>
      </geometry>
      <material name="Red">
        <color rgba=".8 .2 .1 1"/>
      </material>
    </visual>
    <collision>
      <origin rpy="0 0 0" xyz="0 0 0"/>
      <geometry>
        <box size="0.02 0.05 0.05"/>
      </geometry>
    </collision>
    <inertial>
      <mass value=".01"/>
      <inertia ixx=".003" ixy="0" ixz="0" iyy=".003" iyz="0" izz=".003"/>
    </inertial>
  </link>
  <joint name="camera1_joint" type="fixed">
    <parent link="main_body"/>
    <child link="camera1"/>
    <origin rpy="0 0 0" xyz="0.28 0.1 -0.07"/>
  </joint>
  <gazebo reference="camera1">
    <mu1> .2 </mu1>
    <mu2> .2 </mu2>
    <material> Gazebo/Red </material>
    <selfCollide> false </selfCollide>
  </gazebo>
  <!--CAMERA LENS -->
  <link name="camera1_lens">
    <visual>
      <origin rpy="0 1.57075 0" xyz="0.015 0 0"/>
      <geometry>
        <cylinder length="0.01" radius="0.018"/>
      </geometry>
      <material name="Black">
        <color rgba="0 0 0 1"/>
      </material>
    </visual>
    <collision>
      <origin rpy="0 1.57075 0" xyz="0.015 0 0"/>
      <geometry>
        <cylinder length="0.01" radius="0.018"/>
      </geometry>
    </collision>
    <inertial>
      <mass value=".01"/>
      <inertia ixx=".003" ixy="0" ixz="0" iyy=".003" iyz="0" izz=".003"/>
    </inertial>
  </link>
  <joint name="camera1_lens_joint" type="fixed">
    <parent link="main_body"/>
    <child link="camera1_lens"/>
    <origin rpy="0 0 0" xyz="0.28 0.1 -0.07"/>
  </joint>
  <gazebo reference="camera1_lens">
    <mu1> .2 </mu1>
    <mu2> .2 </mu2>
    <material> Gazebo/Black </material>
    <selfCollide> false </selfCollide>
  </gazebo>
  <gazebo reference="camera1">
    <sensor name="camera1" type="camera">
      <update_rate> 10.0 </update_rate>
      <camera name="{name}">
        <horizontal_fov>1.3962634</horizontal_fov>
        <image>
          <width>320</width>
          <height>240</height>
          <format>B8G8R8</format>
        </image>
        <clip>
          <near>0.02</near>
          <far>300</far>
        </clip>
        <noise>
          <type>gaussian</type>
          <mean>0.0</mean>
          <stddev>0.007</stddev>
        </noise>
      </camera>
      <plugin filename="libgazebo_ros_camera.so" name="camera_controller">
        <alwaysOn>True</alwaysOn>
        <updateRate>0.0</updateRate>
        <cameraName>rover_camera1</cameraName>
        <imageTopicName>image_raw</imageTopicName>
        <cameraInfoTopicName>camera_info</cameraInfoTopicName>
        <frameName>camera_link</frameName>
        <hackBaseline>0.07</hackBaseline>
        <distortionK1>0.0</distortionK1>
        <distortionK2>0.0</distortionK2>
        <distortionK3>0.0</distortionK3>
        <distortionT1>0.0</distortionT1>
        <distortionT2>0.0</distortionT2>
      </plugin>
    </sensor>
  </gazebo>
  <!--CAMERA BOARD -->
  <link name="camera2">
    <visual>
      <origin rpy="0 0 0" xyz="0 0 0"/>
      <geometry>
        <box size="0.02 0.05 0.05"/>
      </geometry>
      <material name="Red">
        <color rgba=".8 .2 .1 1"/>
      </material>
    </visual>
    <collision>
      <origin rpy="0 0 0" xyz="0 0 0"/>
      <geometry>
        <box size="0.02 0.05 0.05"/>
      </geometry>
    </collision>
    <inertial>
      <mass value=".01"/>
      <inertia ixx=".003" ixy="0" ixz="0" iyy=".003" iyz="0" izz=".003"/>
    </inertial>
  </link>
  <joint name="camera2_joint" type="fixed">
    <parent link="main_body"/>
    <child link="camera2"/>
    <origin rpy="0 0 0" xyz="0.28 -0.1 -0.07"/>
  </joint>
  <gazebo reference="camera2">
    <mu1> .2 </mu1>
    <mu2> .2 </mu2>
    <material> Gazebo/Red </material>
    <selfCollide> false </selfCollide>
  </gazebo>
  <!--CAMERA LENS -->
  <link name="camera2_lens">
    <visual>
      <origin rpy="0 1.57075 0" xyz="0.015 0 0"/>
      <geometry>
        <cylinder length="0.01" radius="0.018"/>
      </geometry>
      <material name="Black">
        <color rgba="0 0 0 1"/>
      </material>
    </visual>
    <collision>
      <origin rpy="0 1.57075 0" xyz="0.015 0 0"/>
      <geometry>
        <cylinder length="0.01" radius="0.018"/>
      </geometry>
    </collision>
    <inertial>
      <mass value=".01"/>
      <inertia ixx=".003" ixy="0" ixz="0" iyy=".003" iyz="0" izz=".003"/>
    </inertial>
  </link>
  <joint name="camera2_lens_joint" type="fixed">
    <parent link="main_body"/>
    <child link="camera2_lens"/>
    <origin rpy="0 0 0" xyz="0.28 -0.1 -0.07"/>
  </joint>
  <gazebo reference="camera2_lens">
    <mu1> .2 </mu1>
    <mu2> .2 </mu2>
    <material> Gazebo/Black </material>
    <selfCollide> false </selfCollide>
  </gazebo>
  <gazebo reference="camera2">
    <sensor name="camera2" type="camera">
      <update_rate> 10.0 </update_rate>
      <camera name="{name}">
        <horizontal_fov>1.3962634</horizontal_fov>
        <image>
          <width>320</width>
          <height>240</height>
          <format>B8G8R8</format>
        </image>
        <clip>
          <near>0.02</near>
          <far>300</far>
        </clip>
        <noise>
          <type>gaussian</type>
          <mean>0.0</mean>
          <stddev>0.007</stddev>
        </noise>
      </camera>
      <plugin filename="libgazebo_ros_camera.so" name="camera_controller">
        <alwaysOn>True</alwaysOn>
        <updateRate>0.0</updateRate>
        <cameraName>rover_camera2</cameraName>
        <imageTopicName>image_raw</imageTopicName>
        <cameraInfoTopicName>camera_info</cameraInfoTopicName>
        <frameName>camera_link</frameName>
        <hackBaseline>0.07</hackBaseline>
        <distortionK1>0.0</distortionK1>
        <distortionK2>0.0</distortionK2>
        <distortionK3>0.0</distortionK3>
        <distortionT1>0.0</distortionT1>
        <distortionT2>0.0</distortionT2>
      </plugin>
    </sensor>
  </gazebo>
  <!--CAMERA BOARD -->
  <link name="camera3">
    <visual>
      <origin rpy="0 0 0" xyz="0 0 0"/>
      <geometry>
        <box size="0.02 0.05 0.05"/>
      </geometry>
      <material name="Red">
        <color rgba=".8 .2 .1 1"/>
      </material>
    </visual>
    <collision>
      <origin rpy="0 0 0" xyz="0 0 0"/>
      <geometry>
        <box size="0.02 0.05 0.05"/>
      </geometry>
    </collision>
    <inertial>
      <mass value=".01"/>
      <inertia ixx=".003" ixy="0" ixz="0" iyy=".003" iyz="0" izz=".003"/>
    </inertial>
  </link>
  <joint name="camera3_joint" type="fixed">
    <parent link="tower_pitch"/>
    <child link="camera3"/>
    <origin rpy="0 0 0" xyz="0.06 0 0"/>
  </joint>
  <gazebo reference="camera3">
    <mu1> .2 </mu1>
    <mu2> .2 </mu2>
    <material> Gazebo/Red </material>
    <selfCollide> false </selfCollide>
  </gazebo>
  <!--CAMERA LENS -->
  <link name="camera3_lens">
    <visual>
      <origin rpy="0 1.57075 0" xyz="0.015 0 0"/>
      <geometry>
        <cylinder length="0.01" radius="0.018"/>
      </geometry>
      <material name="Black">
        <color rgba="0 0 0 1"/>
      </material>
    </visual>
    <collision>
      <origin rpy="0 1.57075 0" xyz="0.015 0 0"/>
      <geometry>
        <cylinder length="0.01" radius="0.018"/>
      </geometry>
    </collision>
    <inertial>
      <mass value=".01"/>
      <inertia ixx=".003" ixy="0" ixz="0" iyy=".003" iyz="0" izz=".003"/>
    </inertial>
  </link>
  <joint name="camera3_lens_joint" type="fixed">
    <parent link="tower_pitch"/>
    <child link="camera3_lens"/>
    <origin rpy="0 0 0" xyz="0.06 0 0"/>
  </joint>
  <gazebo reference="camera3_lens">
    <mu1> .2 </mu1>
    <mu2> .2 </mu2>
    <material> Gazebo/Black </material>
    <selfCollide> false </selfCollide>
  </gazebo>
  <gazebo reference="camera3">
    <sensor name="camera3" type="camera">
      <update_rate> 10.0 </update_rate>
      <camera name="{name}">
        <horizontal_fov>1.3962634</horizontal_fov>
        <image>
          <width>320</width>
          <height>240</height>
          <format>B8G8R8</format>
        </image>
        <clip>
          <near>0.02</near>
          <far>300</far>
        </clip>
        <noise>
          <type>gaussian</type>
          <mean>0.0</mean>
          <stddev>0.007</stddev>
        </noise>
      </camera>
      <plugin filename="libgazebo_ros_camera.so" name="camera_controller">
        <alwaysOn>True</alwaysOn>
        <updateRate>0.0</updateRate>
        <cameraName>rover_camera3</cameraName>
        <imageTopicName>image_raw</imageTopicName>
        <cameraInfoTopicName>camera_info</cameraInfoTopicName>
        <frameName>camera_link</frameName>
        <hackBaseline>0.07</hackBaseline>
        <distortionK1>0.0</distortionK1>
        <distortionK2>0.0</distortionK2>
        <distortionK3>0.0</distortionK3>
        <distortionT1>0.0</distortionT1>
        <distortionT2>0.0</distortionT2>
      </plugin>
    </sensor>
  </gazebo>
  <!-- LINK -->
  <link name="link_0">
    <visual>
      <origin rpy="0 0 0" xyz="0 0 0"/>
      <geometry>
        <cylinder length="0.05" radius="0.1"/>
      </geometry>
      <material name="blue">
        <color rgba=".2 .2 .5 1"/>
      </material>
    </visual>
    <visual>
      <origin rpy="1.57075 0 0" xyz="0 0 0.025"/>
      <geometry>
        <cylinder length="0.1" radius="0.07"/>
      </geometry>
      <material name="blue">
        <color rgba=".2 .2 .5 1"/>
      </material>
    </visual>
    <collision>
      <origin rpy="0 0 0" xyz="0 0 0"/>
      <geometry>
        <cylinder length="0.05" radius="0.1"/>
      </geometry>
    </collision>
    <collision>
      <origin rpy="1.57075 0 0" xyz="0 0 0.025"/>
      <geometry>
        <cylinder length="0.1" radius="0.07"/>
      </geometry>
    </collision>
    <inertial>
      <mass value="1"/>
      <inertia ixx=".003" ixy=".00" ixz=".00" iyy=".003" iyz=".00" izz=".003"/>
    </inertial>
  </link>
  <gazebo reference="link_0">
    <mu1> .2 </mu1>
    <mu2> .2 </mu2>
    <material> Gazebo/Orange </material>
    <selfCollide> False </selfCollide>
    <implicitSpringDamper> True </implicitSpringDamper>
  </gazebo>
  <!-- JOINT -->
  <joint name="link_0_joint" type="revolute">
    <parent link="main_body"/>
    <child link="link_0"/>
    <origin rpy="0 0 0" xyz="0.15 0 0.125"/>
    <axis xyz="0 0 -1"/>
    <limit effort="100" lower="-3.14" upper="3.14" velocity="1"/>
    <dynamics damping="1"/>
  </joint>
  <!--gazebo reference="${name}_joint">
            <stopCfm>0.8</stopCfm>
            <stopErp>0.5</stopErp>
            <provideFeedback>true</provideFeedback>
            <implicitSpringDamper>true</implicitSpringDamper>
            <fudgeFactor>0.0</fudgeFactor>
        </gazebo-->
  <gazebo>
    <plugin filename="libJointLimiter.so" name="link_0_joint_limiter">
      <joint>link_0_joint</joint>
      <topic>/rover/link_0_velocity_controller</topic>
      <lower>-3.14</lower>
      <upper>3.14</upper>
    </plugin>
  </gazebo>
  <gazebo>
    <plugin filename="libControllerPID.so" name="link_0_controller">
      <joint>link_0_joint</joint>
      <topic>/rover/link_0_velocity_controller</topic>
      <Kp>20</Kp>
      <Ki>2</Ki>
      <Kd>1</Kd>
    </plugin>
  </gazebo>
  <!-- TRANSMISSION -->
  <!--transmission name="${name}_transmission">
            <type>transmission_interface/SimpleTransmission</type>
            <joint name="${name}_joint">
                <hardwareInterface>EffortJointInterface</hardwareInterface>
            </joint>
            <actuator name="${name}_motor">
                <hardwareInterface>EffortJointInterface</hardwareInterface>
                <mechanicalReduction>1</mechanicalReduction>
            </actuator>
        </transmission-->
  <link name="link_1">
    <visual>
      <origin rpy="0 0 0" xyz="-0.25 0 0"/>
      <geometry>
        <box size="0.5 0.07 0.07"/>
      </geometry>
      <material name="light_blue">
        <color rgba=".3 .3 .6 1"/>
      </material>
    </visual>
    <visual>
      <origin rpy="1.57075 0 0" xyz="-0.5 0 0.035"/>
      <geometry>
        <cylinder length="0.07" radius="0.07"/>
      </geometry>
      <material name="light_blue">
        <color rgba=".3 .3 .6 1"/>
      </material>
    </visual>
    <collision>
      <origin rpy="0 0 0" xyz="-0.25 0 0"/>
      <geometry>
        <box size="0.5 0.07 0.07"/>
      </geometry>
    </collision>
    <collision>
      <origin rpy="1.57075 0 0" xyz="-0.5 0 0.035"/>
      <geometry>
        <cylinder length="0.07" radius="0.07"/>
      </geometry>
    </collision>
    <inertial>
      <origin rpy="0 0 0" xyz="-0.25 0 0"/>
      <mass value="1"/>
      <inertia ixx=".003" ixy="0.000" ixz="0.000" iyy=".003" iyz="0.000" izz=".003"/>
    </inertial>
  </link>
  <gazebo reference="link_1">
    <mu1> .2 </mu1>
    <mu2> .2 </mu2>
    <material> Gazebo/Blue </material>
    <selfCollide>False</selfCollide>
  </gazebo>
  <joint name="link_1_joint" type="revolute">
    <parent link="link_0"/>
    <child link="link_1"/>
    <origin rpy="0 0 0" xyz="0 0 0.06"/>
    <axis xyz="0 1 0"/>
    <limit effort="100" lower="0" upper="3.14" velocity="1"/>
    <dynamics damping="1"/>
  </joint>
  <!--gazebo reference="${name}_joint">
            <stopCfm>0.5</stopCfm>
            <stopErp>0.8</stopErp>
            <provideFeedback>true</provideFeedback>
            <implicitSpringDamper>true</implicitSpringDamper>
            <fudgeFactor>0.0</fudgeFactor>
        </gazebo-->
  <gazebo>
    <plugin filename="libJointLimiter.so" name="link_1_joint_limiter">
      <joint>link_1_joint</joint>
      <topic>/rover/link_1_velocity_controller</topic>
      <lower>0</lower>
      <upper>3.14</upper>
    </plugin>
  </gazebo>
  <gazebo>
    <plugin filename="libControllerPID.so" name="link_1_controller">
      <joint>link_1_joint</joint>
      <topic>/rover/link_1_velocity_controller</topic>
      <Kp>30</Kp>
      <Ki>3</Ki>
      <Kd>2</Kd>
    </plugin>
  </gazebo>
  <!--transmission name="${name}_transmission">
            <type>transmission_interface/SimpleTransmission</type>
            <joint name="${name}_joint">
                <hardwareInterface>EffortJointInterface</hardwareInterface>
            </joint>
            <actuator name="${name}_motor">
                <hardwareInterface>EffortJointInterface</hardwareInterface>
                <mechanicalReduction>1</mechanicalReduction>
            </actuator>
        </transmission-->
  <link name="link_2">
    <visual>
      <origin rpy="0 0 0" xyz="0.125 0 0.025"/>
      <geometry>
        <box size="0.25 0.05 0.05"/>
      </geometry>
      <material name="link_2_color">
        <color rgba=".4 .4 .8 1"/>
      </material>
    </visual>
    <visual>
      <origin rpy="1.57075 0 0" xyz="0.25 0 0.025"/>
      <geometry>
        <cylinder length="0.05" radius="0.025"/>
      </geometry>
      <material name="link_2_color">
        <color rgba=".4 .4 .8 1"/>
      </material>
    </visual>
    <collision>
      <origin rpy="0 0 0" xyz="0.125 0 0.025"/>
      <geometry>
        <box size="0.25 0.05 0.05"/>
      </geometry>
    </collision>
    <collision>
      <origin rpy="1.57075 0 0" xyz="0.25 0 0.025"/>
      <geometry>
        <cylinder length="0.05" radius="0.025"/>
      </geometry>
    </collision>
    <inertial>
      <origin rpy="0 0 0" xyz="0.125 0 0.025"/>
      <mass value="1"/>
      <inertia ixx=".003" ixy="0.000" ixz="0.000" iyy=".003" iyz="0.000" izz=".003"/>
    </inertial>
  </link>
  <gazebo reference="link_2">
    <mu1> .2 </mu1>
    <mu2> .2 </mu2>
    <material> Gazebo/Blue </material>
    <selfCollide>False</selfCollide>
  </gazebo>
  <joint name="link_2_joint" type="revolute">
    <parent link="link_1"/>
    <child link="link_2"/>
    <origin rpy="0 0 0" xyz="-0.5 0 0.035"/>
    <axis xyz="0 -1 0"/>
    <limit effort="100" lower="0" upper="5" velocity="1"/>
    <dynamics damping="10"/>
  </joint>
  <!--gazebo reference="${name}_joint">
            <stopCfm>0.8</stopCfm>
            <stopErp>0.5</stopErp>
            <provideFeedback>true</provideFeedback>
            <implicitSpringDamper>true</implicitSpringDamper>
            <fudgeFactor>0.0</fudgeFactor>
        </gazebo-->
  <gazebo>
    <plugin filename="libJointLimiter.so" name="link_2_joint_limiter">
      <joint>link_2_joint</joint>
      <topic>/rover/link_2_velocity_controller</topic>
      <lower>0</lower>
      <upper>5</upper>
    </plugin>
  </gazebo>
  <gazebo>
    <plugin filename="libControllerPID.so" name="link_2_controller">
      <joint>link_2_joint</joint>
      <topic>/rover/link_2_velocity_controller</topic>
      <Kp>30</Kp>
      <Ki>3</Ki>
      <Kd>2</Kd>
    </plugin>
  </gazebo>
  <!--transmission name="${name}_transmission">
            <type>transmission_interface/SimpleTransmission</type>
            <joint name="${name}_joint">
                <hardwareInterface>EffortJointInterface</hardwareInterface>
            </joint>
            <actuator name="${name}_motor">
                <hardwareInterface>EffortJointInterface</hardwareInterface>
                <mechanicalReduction>1</mechanicalReduction>
            </actuator>
        </transmission-->
  <link name="link_3">
    <visual>
      <origin rpy="0 0 0" xyz="0.125 0 0"/>
      <geometry>
        <box size="0.25 0.04 0.04"/>
      </geometry>
      <material name="link_3_color">
        <color rgba=".4 .4 .8 1"/>
      </material>
    </visual>
    <collision>
      <origin rpy="0 0 0" xyz="0.125 0 0"/>
      <geometry>
        <box size="0.25 0.04 0.04"/>
      </geometry>
    </collision>
    <inertial>
      <origin rpy="0 0 0" xyz="0.125 0 0.02"/>
      <mass value="1"/>
      <inertia ixx=".003" ixy="0.000" ixz="0.000" iyy=".003" iyz="0.000" izz=".003"/>
    </inertial>
  </link>
  <gazebo reference="link_3">
    <mu1> .2 </mu1>
    <mu2> .2 </mu2>
    <material> Gazebo/Blue </material>
    <selfCollide>False</selfCollide>
  </gazebo>
  <joint name="link_3_joint" type="revolute">
    <parent link="link_2"/>
    <child link="link_3"/>
    <origin rpy="0 0 0" xyz="0.25 0 0.025"/>
    <axis xyz="0 -1 0"/>
    <limit effort="30" lower="-3.14" upper="3.14" velocity="1"/>
    <dynamics damping="10"/>
  </joint>
  <!--gazebo reference="${name}_joint">
            <stopCfm>0.8</stopCfm>
            <stopErp>0.5</stopErp>
            <provideFeedback>true</provideFeedback>
            <implicitSpringDamper>true</implicitSpringDamper>
            <fudgeFactor>0.0</fudgeFactor>
        </gazebo-->
  <gazebo>
    <plugin filename="libJointLimiter.so" name="link_3_joint_limiter">
      <joint>link_3_joint</joint>
      <topic>/rover/link_3_velocity_controller</topic>
      <lower>-3.14</lower>
      <upper>3.14</upper>
    </plugin>
  </gazebo>
  <gazebo>
    <plugin filename="libControllerPID.so" name="link_3_controller">
      <joint>link_3_joint</joint>
      <topic>/rover/link_3_velocity_controller</topic>
      <Kp>20</Kp>
      <Ki>0</Ki>
      <Kd>2</Kd>
    </plugin>
  </gazebo>
  <gazebo reference="link_3">
    <mu1> .2 </mu1>
    <mu2> .2 </mu2>
    <material> Gazebo/Blue </material>
    <selfCollide>True</selfCollide>
    <!--kp>1.0</kp>
            <kd>1.0</kd>
            <stopCfm>0.8</stopCfm>
            <stopErp>0.5</stopErp>
            <provideFeedback>true</provideFeedback>
            <cfmDamping>true</cfmDamping>
            <fudgeFactor>0.0</fudgeFactor-->
  </gazebo>
  <!--transmission name="${name}_transmission">
            <type>transmission_interface/SimpleTransmission</type>
            <joint name="${name}_joint">
                <hardwareInterface>EffortJointInterface</hardwareInterface>
            </joint>
            <actuator name="${name}_motor">
                <hardwareInterface>EffortJointInterface</hardwareInterface>
                <mechanicalReduction>1</mechanicalReduction>
            </actuator>
        </transmission-->
  <link name="link_4">
    <visual>
      <origin rpy="0 0 0" xyz="0.025 0 0"/>
      <geometry>
        <box size="0.05 0.2 0.05"/>
      </geometry>
      <material name="link_4_color">
        <color rgba=".4 .4 .8 1"/>
      </material>
    </visual>
    <collision>
      <origin rpy="0 0 0" xyz="0.025 0 0"/>
      <geometry>
        <box size="0.05 0.2 0.05"/>
      </geometry>
    </collision>
    <inertial>
      <origin rpy="0 0 0" xyz="0.025 0 0.025"/>
      <mass value="1"/>
      <inertia ixx=".003" ixy="0.000" ixz="0.000" iyy=".003" iyz="0.000" izz=".003"/>
    </inertial>
  </link>
  <gazebo reference="link_4">
    <mu1> .2 </mu1>
    <mu2> .2 </mu2>
    <material> Gazebo/Blue </material>
    <selfCollide>False</selfCollide>
  </gazebo>
  <joint name="link_4_joint" type="revolute">
    <parent link="link_3"/>
    <child link="link_4"/>
    <origin rpy="0 0 0" xyz="0.25 0 0"/>
    <axis xyz="1 0 0"/>
    <limit effort="40" lower="-3.14" upper="3.14" velocity="3"/>
    <dynamics damping="1"/>
  </joint>
  <!--gazebo reference="${name}_joint">
            <stopCfm>0.8</stopCfm>
            <stopErp>0.5</stopErp>
            <provideFeedback>true</provideFeedback>
            <implicitSpringDamper>true</implicitSpringDamper>
            <fudgeFactor>0.0</fudgeFactor>
        </gazebo-->
  <gazebo>
    <plugin filename="libJointLimiter.so" name="link_4_joint_limiter">
      <joint>link_4_joint</joint>
      <topic>/rover/link_4_velocity_controller</topic>
      <lower>-3.14</lower>
      <upper>3.14</upper>
    </plugin>
  </gazebo>
  <gazebo>
    <plugin filename="libControllerPID.so" name="link_4_controller">
      <joint>link_4_joint</joint>
      <topic>/rover/link_4_velocity_controller</topic>
      <Kp>1.05</Kp>
      <Ki>0</Ki>
      <Kd>0.02</Kd>
    </plugin>
  </gazebo>
  <gazebo reference="link_4">
    <mu1> .2 </mu1>
    <mu2> .2 </mu2>
    <material> Gazebo/Yellow </material>
    <selfCollide>True</selfCollide>
    <!--kp>1.0</kp>
            <kd>1.0</kd>
            <stopCfm>0.8</stopCfm>
            <stopErp>0.5</stopErp>
            <provideFeedback>true</provideFeedback>
            <cfmDamping>true</cfmDamping>
            <fudgeFactor>0.0</fudgeFactor-->
  </gazebo>
  <!--transmission name="${name}_transmission">
            <type>transmission_interface/SimpleTransmission</type>
            <joint name="${name}_joint">
                <hardwareInterface>EffortJointInterface</hardwareInterface>
            </joint>
            <actuator name="${name}_motor">
                <hardwareInterface>EffortJointInterface</hardwareInterface>
                <mechanicalReduction>1</mechanicalReduction>
            </actuator>
        </transmission-->
  <link name="finger1">
    <visual>
      <origin rpy="0 0 0" xyz="0 0 0"/>
      <geometry>
        <box size="0.2 0.02 0.03"/>
      </geometry>
      <material name="finger_color">
        <color rgba=".4 .4 .8 1"/>
      </material>
    </visual>
    <visual>
      <origin rpy="1.57075 0 0" xyz="0.1 0 0"/>
      <geometry>
        <cylinder length="0.02" radius="0.015"/>
      </geometry>
      <material name="finger_color">
        <color rgba=".4 .4 .8 1"/>
      </material>
    </visual>
    <collision>
      <origin rpy="0 0 0" xyz="0 0 0"/>
      <geometry>
        <box size="0.2 0.02 0.03"/>
      </geometry>
    </collision>
    <collision>
      <origin rpy="1.57075 0 0" xyz="0.1 0 0"/>
      <geometry>
        <cylinder length="0.02" radius="0.015"/>
      </geometry>
    </collision>
    <inertial>
      <origin rpy="0 0 0" xyz="0 0 0"/>
      <mass value=".1"/>
      <inertia ixx=".0003" ixy="0.000" ixz="0.000" iyy=".0003" iyz="0.000" izz=".0003"/>
    </inertial>
  </link>
  <gazebo reference="finger1">
    <mu1> 1.0 </mu1>
    <mu2> 1.0 </mu2>
    <material> Gazebo/Yellow </material>
    <selfCollide>False</selfCollide>
  </gazebo>
  <joint name="finger1_joint" type="prismatic">
    <parent link="link_4"/>
    <child link="finger1"/>
    <origin rpy="0 0 0" xyz="0.15 0.09 0"/>
    <axis xyz="0 -1 0"/>
    <limit effort="40" lower="0" upper="0.08" velocity="1"/>
    <dynamics damping=".1"/>
  </joint>
  <!--gazebo reference="${name}_joint">
            <stopCfm>0.8</stopCfm>
            <stopErp>0.5</stopErp>
            <provideFeedback>true</provideFeedback>
            <implicitSpringDamper>true</implicitSpringDamper>
            <fudgeFactor>0.0</fudgeFactor>
        </gazebo-->
  <gazebo>
    <plugin filename="libJointLimiter.so" name="finger1_joint_limiter">
      <joint>finger1_joint</joint>
      <topic>/rover/finger1_velocity_controller</topic>
      <lower>0</lower>
      <upper>0.08</upper>
    </plugin>
  </gazebo>
  <gazebo>
    <plugin filename="libControllerPID.so" name="finger1_controller">
      <joint>finger1_joint</joint>
      <topic>/rover/finger1_velocity_controller</topic>
      <Kp>10</Kp>
      <Ki>0</Ki>
      <Kd>5</Kd>
    </plugin>
  </gazebo>
  <!--transmission name="${name}_transmission">
            <type>transmission_interface/SimpleTransmission</type>
            <joint name="${name}_joint">
                <hardwareInterface>EffortJointInterface</hardwareInterface>
            </joint>
            <actuator name="${name}_motor">
                <hardwareInterface>EffortJointInterface</hardwareInterface>
                <mechanicalReduction>1</mechanicalReduction>
            </actuator>
        </transmission-->
  <link name="finger2">
    <visual>
      <origin rpy="0 0 0" xyz="0 0 0"/>
      <geometry>
        <box size="0.2 0.02 0.03"/>
      </geometry>
      <material name="finger_color">
        <color rgba=".4 .4 .8 1"/>
      </material>
    </visual>
    <visual>
      <origin rpy="1.57075 0 0" xyz="0.1 0 0"/>
      <geometry>
        <cylinder length="0.02" radius="0.015"/>
      </geometry>
      <material name="finger_color">
        <color rgba=".4 .4 .8 1"/>
      </material>
    </visual>
    <collision>
      <origin rpy="0 0 0" xyz="0 0 0"/>
      <geometry>
        <box size="0.2 0.02 0.03"/>
      </geometry>
    </collision>
    <collision>
      <origin rpy="1.57075 0 0" xyz="0.1 0 0"/>
      <geometry>
        <cylinder length="0.02" radius="0.015"/>
      </geometry>
    </collision>
    <inertial>
      <origin rpy="0 0 0" xyz="0 0 0"/>
      <mass value=".1"/>
      <inertia ixx=".0003" ixy="0.000" ixz="0.000" iyy=".0003" iyz="0.000" izz=".0003"/>
    </inertial>
  </link>
  <gazebo reference="finger2">
    <mu1> 1.0 </mu1>
    <mu2> 1.0 </mu2>
    <material> Gazebo/Yellow </material>
    <selfCollide>False</selfCollide>
  </gazebo>
  <joint name="finger2_joint" type="prismatic">
    <parent link="link_4"/>
    <child link="finger2"/>
    <origin rpy="0 0 0" xyz="0.15 -0.09 0"/>
    <axis xyz="0 1 0"/>
    <limit effort="40" lower="0" upper="0.08" velocity="1"/>
    <dynamics damping=".1"/>
  </joint>
  <!--gazebo reference="${name}_joint">
            <stopCfm>0.8</stopCfm>
            <stopErp>0.5</stopErp>
            <provideFeedback>true</provideFeedback>
            <implicitSpringDamper>true</implicitSpringDamper>
            <fudgeFactor>0.0</fudgeFactor>
        </gazebo-->
  <gazebo>
    <plugin filename="libJointLimiter.so" name="finger2_joint_limiter">
      <joint>finger2_joint</joint>
      <topic>/rover/finger2_velocity_controller</topic>
      <lower>0</lower>
      <upper>0.08</upper>
    </plugin>
  </gazebo>
  <gazebo>
    <plugin filename="libControllerPID.so" name="finger2_controller">
      <joint>finger2_joint</joint>
      <topic>/rover/finger2_velocity_controller</topic>
      <Kp>10</Kp>
      <Ki>0</Ki>
      <Kd>5</Kd>
    </plugin>
  </gazebo>
  <!--transmission name="${name}_transmission">
            <type>transmission_interface/SimpleTransmission</type>
            <joint name="${name}_joint">
                <hardwareInterface>EffortJointInterface</hardwareInterface>
            </joint>
            <actuator name="${name}_motor">
                <hardwareInterface>EffortJointInterface</hardwareInterface>
                <mechanicalReduction>1</mechanicalReduction>
            </actuator>
        </transmission-->
  <!--CAMERA BOARD -->
  <link name="camera4">
    <visual>
      <origin rpy="0 0 0" xyz="0 0 0"/>
      <geometry>
        <box size="0.02 0.05 0.05"/>
      </geometry>
      <material name="Red">
        <color rgba=".8 .2 .1 1"/>
      </material>
    </visual>
    <collision>
      <origin rpy="0 0 0" xyz="0 0 0"/>
      <geometry>
        <box size="0.02 0.05 0.05"/>
      </geometry>
    </collision>
    <inertial>
      <mass value=".01"/>
      <inertia ixx=".003" ixy="0" ixz="0" iyy=".003" iyz="0" izz=".003"/>
    </inertial>
  </link>
  <joint name="camera4_joint" type="fixed">
    <parent link="link_3"/>
    <child link="camera4"/>
    <origin rpy="0 0 0" xyz="0.15 0 0.1"/>
  </joint>
  <gazebo reference="camera4">
    <mu1> .2 </mu1>
    <mu2> .2 </mu2>
    <material> Gazebo/Red </material>
    <selfCollide> false </selfCollide>
  </gazebo>
  <!--CAMERA LENS -->
  <link name="camera4_lens">
    <visual>
      <origin rpy="0 1.57075 0" xyz="0.015 0 0"/>
      <geometry>
        <cylinder length="0.01" radius="0.018"/>
      </geometry>
      <material name="Black">
        <color rgba="0 0 0 1"/>
      </material>
    </visual>
    <collision>
      <origin rpy="0 1.57075 0" xyz="0.015 0 0"/>
      <geometry>
        <cylinder length="0.01" radius="0.018"/>
      </geometry>
    </collision>
    <inertial>
      <mass value=".01"/>
      <inertia ixx=".003" ixy="0" ixz="0" iyy=".003" iyz="0" izz=".003"/>
    </inertial>
  </link>
  <joint name="camera4_lens_joint" type="fixed">
    <parent link="link_3"/>
    <child link="camera4_lens"/>
    <origin rpy="0 0 0" xyz="0.15 0 0.1"/>
  </joint>
  <gazebo reference="camera4_lens">
    <mu1> .2 </mu1>
    <mu2> .2 </mu2>
    <material> Gazebo/Black </material>
    <selfCollide> false </selfCollide>
  </gazebo>
  <gazebo reference="camera4">
    <sensor name="camera4" type="camera">
      <update_rate> 10.0 </update_rate>
      <camera name="{name}">
        <horizontal_fov>1.3962634</horizontal_fov>
        <image>
          <width>320</width>
          <height>240</height>
          <format>B8G8R8</format>
        </image>
        <clip>
          <near>0.02</near>
          <far>300</far>
        </clip>
        <noise>
          <type>gaussian</type>
          <mean>0.0</mean>
          <stddev>0.007</stddev>
        </noise>
      </camera>
      <plugin filename="libgazebo_ros_camera.so" name="camera_controller">
        <alwaysOn>True</alwaysOn>
        <updateRate>0.0</updateRate>
        <cameraName>rover_camera4</cameraName>
        <imageTopicName>image_raw</imageTopicName>
        <cameraInfoTopicName>camera_info</cameraInfoTopicName>
        <frameName>camera_link</frameName>
        <hackBaseline>0.07</hackBaseline>
        <distortionK1>0.0</distortionK1>
        <distortionK2>0.0</distortionK2>
        <distortionK3>0.0</distortionK3>
        <distortionT1>0.0</distortionT1>
        <distortionT2>0.0</distortionT2>
      </plugin>
    </sensor>
  </gazebo>
</robot>

